<?xml version="1.0"?>
<robot name="iris_placeholder" xmlns:xacro="http://ros.org/wiki/xacro">

  <!-- Base Link -->
  <link name="base_link">
    <visual>
      <geometry>
        <box size="0.3 0.3 0.1"/>
      </geometry>
      <material>
        <color rgba="0.6 0.6 0.6 1.0"/>
      </material>
    </visual>
  </link>

  <!-- Rotor 0 -->
  <link name="rotor_0">
    <visual>
      <geometry>
        <cylinder length="0.02" radius="0.05"/>
      </geometry>
      <material>
        <color rgba="1.0 0.0 0.0 1.0"/>
      </material>
    </visual>
  </link>

  <joint name="rotor_0_joint" type="continuous">
    <parent link="base_link"/>
    <child link="rotor_0"/>
    <origin xyz="0.2 0.2 0.05" rpy="0 0 0"/>
    <axis xyz="0 0 1"/>
  </joint>

  <!-- Rotor 1 -->
  <link name="rotor_1">
    <visual>
      <geometry>
        <cylinder length="0.02" radius="0.05"/>
      </geometry>
      <material>
        <color rgba="0.0 1.0 0.0 1.0"/>
      </material>
    </visual>
  </link>

  <joint name="rotor_1_joint" type="continuous">
    <parent link="base_link"/>
    <child link="rotor_1"/>
    <origin xyz="-0.2 0.2 0.05" rpy="0 0 0"/>
    <axis xyz="0 0 1"/>
  </joint>

  <!-- Rotor 2 -->
  <link name="rotor_2">
    <visual>
      <geometry>
        <cylinder length="0.02" radius="0.05"/>
      </geometry>
      <material>
        <color rgba="0.0 0.0 1.0 1.0"/>
      </material>
    </visual>
  </link>

  <joint name="rotor_2_joint" type="continuous">
    <parent link="base_link"/>
    <child link="rotor_2"/>
    <origin xyz="-0.2 -0.2 0.05" rpy="0 0 0"/>
    <axis xyz="0 0 1"/>
  </joint>

  <!-- Rotor 3 -->
  <link name="rotor_3">
    <visual>
      <geometry>
        <cylinder length="0.02" radius="0.05"/>
      </geometry>
      <material>
        <color rgba="1.0 1.0 0.0 1.0"/>
      </material>
    </visual>
  </link>

  <joint name="rotor_3_joint" type="continuous">
    <parent link="base_link"/>
    <child link="rotor_3"/>
    <origin xyz="0.2 -0.2 0.05" rpy="0 0 0"/>
    <axis xyz="0 0 1"/>
  </joint>

  <!-- Lidar Link -->
  <link name="base_scan">
    <visual>
      <geometry>
        <box size="0.05 0.05 0.05"/>
      </geometry>
      <material>
        <color rgba="0.5 0.5 0.5 1.0"/>
      </material>
    </visual>
  </link>

  <joint name="lidar_joint" type="fixed">
    <parent link="base_link"/>
    <child link="base_scan"/>
    <origin xyz="0 0 0.1" rpy="0 0 0"/>
  </joint>

</robot>
